Workbook

Sheet Summary Sheet
A1: BHARATI VIDYAPEETH’S
A2: COLLEGE OF ENGINEERING FOR WOMEN, PUNE
A3: DEPARTMENT OF ENGINEERING SCIENCES AND ALLIED ENGINEERING
A4: Academic Year | B4: 2024-25
A5: Subject
A6: Semester
A7: Class | B7: F.E. | C7: Division
C8: Comprehensive Continuous Evaluation | H8: Attendance
A9: Roll No | B9: Name of Student | C9: EM-1 | D9: EP | E9: BEE | F9: EM | G9: FPL
B10: Marks | C10: 30 | D10: 30 | E10: 30 | F10: 30 | G10: 30
B11: Date of Conduction
A12: 401 | B12: TIWARY ADITA AJIT | C12: ='Engg Mathematics'!H13 -> 0 | D12: ='Engg. Physics'!H13 -> 0 | E12: ='Basic Electrical'!H13 -> 0 | F12: ='Engg. Mechanics'!H13 -> 0 | G12: =FPL!H13 -> 0 | H12: =AVERAGE('Engg Mathematics'!I13+'Engg. Physics'!I13+'Basic Electrical'!I13+'Engg. Mechanics'!I13+FPL!I13) -> 0
A13: 402 | B13: FULZELE AMRUTA HIRALAL | C13: ='Engg Mathematics'!H14 -> 0 | D13: ='Engg. Physics'!H14 -> 0 | E13: ='Basic Electrical'!H14 -> 0 | F13: ='Engg. Mechanics'!H14 -> 0 | G13: =FPL!H14 -> 0 | H13: =AVERAGE('Engg Mathematics'!I14+'Engg. Physics'!I14+'Basic Electrical'!I14+'Engg. Mechanics'!I14+FPL!I14) -> 0
A14: 403 | B14: ANBHULE ADITI NAMDEO | C14: ='Engg Mathematics'!H15 -> 0 | D14: ='Engg. Physics'!H15 -> 0 | E14: ='Basic Electrical'!H15 -> 0 | F14: ='Engg. Mechanics'!H15 -> 0 | G14: =FPL!H15 -> 0 | H14: =AVERAGE('Engg Mathematics'!I15+'Engg. Physics'!I15+'Basic Electrical'!I15+'Engg. Mechanics'!I15+FPL!I15) -> 0
A15: 404 | B15: ANBHULE SHIVANI SANDIP | C15: ='Engg Mathematics'!H16 -> 0 | D15: ='Engg. Physics'!H16 -> 0 | E15: ='Basic Electrical'!H16 -> 0 | F15: ='Engg. Mechanics'!H16 -> 0 | G15: =FPL!H16 -> 0 | H15: =AVERAGE('Engg Mathematics'!I16+'Engg. Physics'!I16+'Basic Electrical'!I16+'Engg. Mechanics'!I16+FPL!I16) -> 0
A16: 405 | B16: SAI PRAJNA B | C16: ='Engg Mathematics'!H17 -> 0 | D16: ='Engg. Physics'!H17 -> 0 | E16: ='Basic Electrical'!H17 -> 0 | F16: ='Engg. Mechanics'!H17 -> 0 | G16: =FPL!H17 -> 0 | H16: =AVERAGE('Engg Mathematics'!I17+'Engg. Physics'!I17+'Basic Electrical'!I17+'Engg. Mechanics'!I17+FPL!I17) -> 0
A17: 406 | B17: BADAGU GRISHMA GANESH | C17: ='Engg Mathematics'!H18 -> 0 | D17: ='Engg. Physics'!H18 -> 0 | E17: ='Basic Electrical'!H18 -> 0 | F17: ='Engg. Mechanics'!H18 -> 0 | G17: =FPL!H18 -> 0 | H17: =AVERAGE('Engg Mathematics'!I18+'Engg. Physics'!I18+'Basic Electrical'!I18+'Engg. Mechanics'!I18+FPL!I18) -> 0
A18: 407 | B18: BANDAL KAVERI MOHAN | C18: ='Engg Mathematics'!H19 -> 0 | D18: ='Engg. Physics'!H19 -> 0 | E18: ='Basic Electrical'!H19 -> 0 | F18: ='Engg. Mechanics'!H19 -> 0 | G18: =FPL!H19 -> 0 | H18: =AVERAGE('Engg Mathematics'!I19+'Engg. Physics'!I19+'Basic Electrical'!I19+'Engg. Mechanics'!I19+FPL!I19) -> 0
A19: 408 | B19: BARVE ASMITA ABHISHEK | C19: ='Engg Mathematics'!H20 -> 0 | D19: ='Engg. Physics'!H20 -> 0 | E19: ='Basic Electrical'!H20 -> 0 | F19: ='Engg. Mechanics'!H20 -> 0 | G19: =FPL!H20 -> 0 | H19: =AVERAGE('Engg Mathematics'!I20+'Engg. Physics'!I20+'Basic Electrical'!I20+'Engg. Mechanics'!I20+FPL!I20) -> 0
A20: 409 | B20: BHOSALE MIHIKA MANSING | C20: ='Engg Mathematics'!H21 -> 0 | D20: ='Engg. Physics'!H21 -> 0 | E20: ='Basic Electrical'!H21 -> 0 | F20: ='Engg. Mechanics'!H21 -> 0 | G20: =FPL!H21 -> 0 | H20: =AVERAGE('Engg Mathematics'!I21+'Engg. Physics'!I21+'Basic Electrical'!I21+'Engg. Mechanics'!I21+FPL!I21) -> 0
A21: 410 | B21: BONDRE ASMITA KAILAS | C21: ='Engg Mathematics'!H22 -> 0 | D21: ='Engg. Physics'!H22 -> 0 | E21: ='Basic Electrical'!H22 -> 0 | F21: ='Engg. Mechanics'!H22 -> 0 | G21: =FPL!H22 -> 0 | H21: =AVERAGE('Engg Mathematics'!I22+'Engg. Physics'!I22+'Basic Electrical'!I22+'Engg. Mechanics'!I22+FPL!I22) -> 0
A22: 411 | B22: CHAVAN HARIPRIYA SATISH | C22: ='Engg Mathematics'!H23 -> 0 | D22: ='Engg. Physics'!H23 -> 0 | E22: ='Basic Electrical'!H23 -> 0 | F22: ='Engg. Mechanics'!H23 -> 0 | G22: =FPL!H23 -> 0 | H22: =AVERAGE('Engg Mathematics'!I23+'Engg. Physics'!I23+'Basic Electrical'!I23+'Engg. Mechanics'!I23+FPL!I23) -> 0
A23: 412 | B23: CHAVAN NEHA BHIVSEN | C23: ='Engg Mathematics'!H24 -> 0 | D23: ='Engg. Physics'!H24 -> 0 | E23: ='Basic Electrical'!H24 -> 0 | F23: ='Engg. Mechanics'!H24 -> 0 | G23: =FPL!H24 -> 0 | H23: =AVERAGE('Engg Mathematics'!I24+'Engg. Physics'!I24+'Basic Electrical'!I24+'Engg. Mechanics'!I24+FPL!I24) -> 0
... A50: 439 | B50: LAWAND RUTUJA RAMESH | C50: ='Engg Mathematics'!H51 -> 0 | D50: ='Engg. Physics'!H51 -> 0 | E50: ='Basic Electrical'!H51 -> 0 | F50: ='Engg. Mechanics'!H51 -> 0 | G50: =FPL!H51 -> 0 | H50: =AVERAGE('Engg Mathematics'!I51+'Engg. Physics'!I51+'Basic Electrical'!I51+'Engg. Mechanics'!I51+FPL!I51) -> 0
A51: 440 | C51: ='Engg Mathematics'!H52 -> 0 | D51: ='Engg. Physics'!H52 -> 0 | E51: ='Basic Electrical'!H52 -> 0 | F51: ='Engg. Mechanics'!H52 -> 0 | G51: =FPL!H52 -> 0 | H51: =AVERAGE('Engg Mathematics'!I52+'Engg. Physics'!I52+'Basic Electrical'!I52+'Engg. Mechanics'!I52+FPL!I52) -> 0
A52: 441 | B52: MAKHARE RIYA TUSHAR | C52: ='Engg Mathematics'!H53 -> 0 | D52: ='Engg. Physics'!H53 -> 0 | E52: ='Basic Electrical'!H53 -> 0 | F52: ='Engg. Mechanics'!H53 -> 0 | G52: =FPL!H53 -> 0 | H52: =AVERAGE('Engg Mathematics'!I53+'Engg. Physics'!I53+'Basic Electrical'!I53+'Engg. Mechanics'!I53+FPL!I53) -> 0
A53: 442 | B53: MHATRE SWARA SURAJ | C53: ='Engg Mathematics'!H54 -> 0 | D53: ='Engg. Physics'!H54 -> 0 | E53: ='Basic Electrical'!H54 -> 0 | F53: ='Engg. Mechanics'!H54 -> 0 | G53: =FPL!H54 -> 0 | H53: =AVERAGE('Engg Mathematics'!I54+'Engg. Physics'!I54+'Basic Electrical'!I54+'Engg. Mechanics'!I54+FPL!I54) -> 0
A54: 443 | B54: MODAK SANIKA ABASAHEB | C54: ='Engg Mathematics'!H55 -> 0 | D54: ='Engg. Physics'!H55 -> 0 | E54: ='Basic Electrical'!H55 -> 0 | F54: ='Engg. Mechanics'!H55 -> 0 | G54: =FPL!H55 -> 0 | H54: =AVERAGE('Engg Mathematics'!I55+'Engg. Physics'!I55+'Basic Electrical'!I55+'Engg. Mechanics'!I55+FPL!I55) -> 0
A55: 444 | B55: MORE SAKSHI PRAKASH | C55: ='Engg Mathematics'!H56 -> 0 | D55: ='Engg. Physics'!H56 -> 0 | E55: ='Basic Electrical'!H56 -> 0 | F55: ='Engg. Mechanics'!H56 -> 0 | G55: =FPL!H56 -> 0 | H55: =AVERAGE('Engg Mathematics'!I56+'Engg. Physics'!I56+'Basic Electrical'!I56+'Engg. Mechanics'!I56+FPL!I56) -> 0
A56: 445 | B56: NETAKE RUTIKA LAXMAN | C56: ='Engg Mathematics'!H57 -> 0 | D56: ='Engg. Physics'!H57 -> 0 | E56: ='Basic Electrical'!H57 -> 0 | F56: ='Engg. Mechanics'!H57 -> 0 | G56: =FPL!H57 -> 0 | H56: =AVERAGE('Engg Mathematics'!I57+'Engg. Physics'!I57+'Basic Electrical'!I57+'Engg. Mechanics'!I57+FPL!I57) -> 0
A57: 446 | B57: PARDESHI RIYA MANOJ | C57: ='Engg Mathematics'!H58 -> 0 | D57: ='Engg. Physics'!H58 -> 0 | E57: ='Basic Electrical'!H58 -> 0 | F57: ='Engg. Mechanics'!H58 -> 0 | G57: =FPL!H58 -> 0 | H57: =AVERAGE('Engg Mathematics'!I58+'Engg. Physics'!I58+'Basic Electrical'!I58+'Engg. Mechanics'!I58+FPL!I58) -> 0
A58: 447 | B58: PATIL SHWETA SACHIN | C58: ='Engg Mathematics'!H59 -> 0 | D58: ='Engg. Physics'!H59 -> 0 | E58: ='Basic Electrical'!H59 -> 0 | F58: ='Engg. Mechanics'!H59 -> 0 | G58: =FPL!H59 -> 0 | H58: =AVERAGE('Engg Mathematics'!I59+'Engg. Physics'!I59+'Basic Electrical'!I59+'Engg. Mechanics'!I59+FPL!I59) -> 0
A59: 448 | B59: PAWAR BHARGAVI BHUSHAN | C59: ='Engg Mathematics'!H60 -> 0 | D59: ='Engg. Physics'!H60 -> 0 | E59: ='Basic Electrical'!H60 -> 0 | F59: ='Engg. Mechanics'!H60 -> 0 | G59: =FPL!H60 -> 0 | H59: =AVERAGE('Engg Mathematics'!I60+'Engg. Physics'!I60+'Basic Electrical'!I60+'Engg. Mechanics'!I60+FPL!I60) -> 0
A60: 449 | B60: PAWAR SUVARNA SURYBHAN | C60: ='Engg Mathematics'!H61 -> 0 | D60: ='Engg. Physics'!H61 -> 0 | E60: ='Basic Electrical'!H61 -> 0 | F60: ='Engg. Mechanics'!H61 -> 0 | G60: =FPL!H61 -> 0 | H60: =AVERAGE('Engg Mathematics'!I61+'Engg. Physics'!I61+'Basic Electrical'!I61+'Engg. Mechanics'!I61+FPL!I61) -> 0
A61: 450 | B61: PHATAK VEDIKA HEMANT | C61: ='Engg Mathematics'!H62 -> 0 | D61: ='Engg. Physics'!H62 -> 0 | E61: ='Basic Electrical'!H62 -> 0 | F61: ='Engg. Mechanics'!H62 -> 0 | G61: =FPL!H62 -> 0 | H61: =AVERAGE('Engg Mathematics'!I62+'Engg. Physics'!I62+'Basic Electrical'!I62+'Engg. Mechanics'!I62+FPL!I62) -> 0
A62: 451 | B62: PUJARI NIKITA JAKAPPA | C62: ='Engg Mathematics'!H63 -> 0 | D62: ='Engg. Physics'!H63 -> 0 | E62: ='Basic Electrical'!H63 -> 0 | F62: ='Engg. Mechanics'!H63 -> 0 | G62: =FPL!H63 -> 0 | H62: =AVERAGE('Engg Mathematics'!I63+'Engg. Physics'!I63+'Basic Electrical'!I63+'Engg. Mechanics'!I63+FPL!I63) -> 0
A63: 452 | B63: RENUSE ASHU RAVINDRA | C63: ='Engg Mathematics'!H64 -> 0 | D63: ='Engg. Physics'!H64 -> 0 | E63: ='Basic Electrical'!H64 -> 0 | F63: ='Engg. Mechanics'!H64 -> 0 | G63: =FPL!H64 -> 0 | H63: =AVERAGE('Engg Mathematics'!I64+'Engg. Physics'!I64+'Basic Electrical'!I64+'Engg. Mechanics'!I64+FPL!I64) -> 0
... A75: 464 | B75: TARALKAR MRUDULA PANKAJ | C75: ='Engg Mathematics'!H76 -> 0 | D75: ='Engg. Physics'!H76 -> 0 | E75: ='Basic Electrical'!H76 -> 0 | F75: ='Engg. Mechanics'!H76 -> 0 | G75: =FPL!H76 -> 0 | H75: =AVERAGE('Engg Mathematics'!I76+'Engg. Physics'!I76+'Basic Electrical'!I76+'Engg. Mechanics'!I76+FPL!I76) -> 0
A76: 465 | B76: TAVHARE RIYA NAWNATH | C76: ='Engg Mathematics'!H77 -> 0 | D76: ='Engg. Physics'!H77 -> 0 | E76: ='Basic Electrical'!H77 -> 0 | F76: ='Engg. Mechanics'!H77 -> 0 | G76: =FPL!H77 -> 0 | H76: =('Engg Mathematics'!I77+'Engg. Physics'!I77+'Basic Electrical'!I77+'Engg. Mechanics'!I77+FPL!I77)/5 -> 0
A77: 466 | B77: TODKAR GUNJAN MANOJ | C77: ='Engg Mathematics'!H78 -> 0 | D77: ='Engg. Physics'!H78 -> 0 | E77: ='Basic Electrical'!H78 -> 0 | F77: ='Engg. Mechanics'!H78 -> 0 | G77: =FPL!H78 -> 0 | H77: =AVERAGE('Engg Mathematics'!I78+'Engg. Physics'!I78+'Basic Electrical'!I78+'Engg. Mechanics'!I78+FPL!I78) -> 0
...

Sheet Engg Mathematics
A1: BHARATI VIDYAPEETH’S
A2: COLLEGE OF ENGINEERING FOR WOMEN, PUNE
A3: DEPARTMENT OF ENGINEERING SCIENCES AND ALLIED ENGINEERING
A4: Academic Year | B4: 2024-25
A5: Subject
A6: Semester
A7: Class | B7: F.E. | C7: Division
C8: Comprehensive Continuous Evaluation | H8: Total Marks | I8: Overall Attendance
A9: Roll No | B9: Name of Student | C9: Unit 1 | D9: Unit 2 | E9: Unit 3 | F9: Unit 4 | G9: Unit 5
C10: Unit Test | E10: Assignment /Case Study | G10: Seminar Presentation/Open book Test/Quiz
B11: Marks | C11: 6 | D11: 6 | E11: 6 | F11: 6 | G11: 6 | H11: =SUM(C11:G11) -> 30
B12: Date of Conduction | H12: =SUM(C12:G12) -> 0
A13: ='Summary Sheet'!A12 -> 401 | B13: ='Summary Sheet'!B12 -> TIWARY ADITA AJIT | H13: =SUM(C13:G13) -> 0
A14: ='Summary Sheet'!A13 -> 402 | B14: ='Summary Sheet'!B13 -> FULZELE AMRUTA HIRALAL | H14: =SUM(C14:G14) -> 0
A15: ='Summary Sheet'!A14 -> 403 | B15: ='Summary Sheet'!B14 -> ANBHULE ADITI NAMDEO | H15: =SUM(C15:G15) -> 0
A16: ='Summary Sheet'!A15 -> 404 | B16: ='Summary Sheet'!B15 -> ANBHULE SHIVANI SANDIP | H16: =SUM(C16:G16) -> 0
A17: ='Summary Sheet'!A16 -> 405 | B17: ='Summary Sheet'!B16 -> SAI PRAJNA B | H17: =SUM(C17:G17) -> 0
A18: ='Summary Sheet'!A17 -> 406 | B18: ='Summary Sheet'!B17 -> BADAGU GRISHMA GANESH | H18: =SUM(C18:G18) -> 0
A19: ='Summary Sheet'!A18 -> 407 | B19: ='Summary Sheet'!B18 -> BANDAL KAVERI MOHAN | H19: =SUM(C19:G19) -> 0
A20: ='Summary Sheet'!A19 -> 408 | B20: ='Summary Sheet'!B19 -> BARVE ASMITA ABHISHEK | H20: =SUM(C20:G20) -> 0
A21: ='Summary Sheet'!A20 -> 409 | B21: ='Summary Sheet'!B20 -> BHOSALE MIHIKA MANSING | H21: =SUM(C21:G21) -> 0
A22: ='Summary Sheet'!A21 -> 410 | B22: ='Summary Sheet'!B21 -> BONDRE ASMITA KAILAS | H22: =SUM(C22:G22) -> 0
A23: ='Summary Sheet'!A22 -> 411 | B23: ='Summary Sheet'!B22 -> CHAVAN HARIPRIYA SATISH | H23: =SUM(C23:G23) -> 0
A24: ='Summary Sheet'!A23 -> 412 | B24: ='Summary Sheet'!B23 -> CHAVAN NEHA BHIVSEN | H24: =SUM(C24:G24) -> 0
... A81: ='Summary Sheet'!A80 -> 469 | B81: ='Summary Sheet'!B80 -> GENDEWAD VEDIKA SHIVAJI | H81: =SUM(C81:G81) -> 0

Sheet Engg. Physics
A1: BHARATI VIDYAPEETH’S
A2: COLLEGE OF ENGINEERING FOR WOMEN, PUNE
A3: DEPARTMENT OF ENGINEERING SCIENCES AND ALLIED ENGINEERING
A4: Academic Year | B4: 2024-25
A5: Subject
A6: Semester
A7: Class | B7: F.E. | C7: Division
C8: Comprehensive Continuous Evaluation | H8: Total Marks | I8: Overall Attendance
A9: Roll No | B9: Name of Student | C9: Unit 1 | D9: Unit 2 | E9: Unit 3 | F9: Unit 4 | G9: Unit 5
C10: Unit Test | E10: Assignment /Case Study | G10: Seminar Presentation/Open book Test/Quiz
B11: Marks | C11: 6 | D11: 6 | E11: 6 | F11: 6 | G11: 6 | H11: =SUM(C11:G11) -> 30
B12: Date of Conduction | H12: =SUM(C12:G12) -> 0
A13: ='Summary Sheet'!A12 -> 401 | B13: ='Summary Sheet'!B12 -> TIWARY ADITA AJIT | H13: =SUM(C13:G13) -> 0
A14: ='Summary Sheet'!A13 -> 402 | B14: ='Summary Sheet'!B13 -> FULZELE AMRUTA HIRALAL | H14: =SUM(C14:G14) -> 0
A15: ='Summary Sheet'!A14 -> 403 | B15: ='Summary Sheet'!B14 -> ANBHULE ADITI NAMDEO | H15: =SUM(C15:G15) -> 0
A16: ='Summary Sheet'!A15 -> 404 | B16: ='Summary Sheet'!B15 -> ANBHULE SHIVANI SANDIP | H16: =SUM(C16:G16) -> 0
A17: ='Summary Sheet'!A16 -> 405 | B17: ='Summary Sheet'!B16 -> SAI PRAJNA B | H17: =SUM(C17:G17) -> 0
A18: ='Summary Sheet'!A17 -> 406 | B18: ='Summary Sheet'!B17 -> BADAGU GRISHMA GANESH | H18: =SUM(C18:G18) -> 0
A19: ='Summary Sheet'!A18 -> 407 | B19: ='Summary Sheet'!B18 -> BANDAL KAVERI MOHAN | H19: =SUM(C19:G19) -> 0
A20: ='Summary Sheet'!A19 -> 408 | B20: ='Summary Sheet'!B19 -> BARVE ASMITA ABHISHEK | H20: =SUM(C20:G20) -> 0
A21: ='Summary Sheet'!A20 -> 409 | B21: ='Summary Sheet'!B20 -> BHOSALE MIHIKA MANSING | H21: =SUM(C21:G21) -> 0
A22: ='Summary Sheet'!A21 -> 410 | B22: ='Summary Sheet'!B21 -> BONDRE ASMITA KAILAS | H22: =SUM(C22:G22) -> 0
A23: ='Summary Sheet'!A22 -> 411 | B23: ='Summary Sheet'!B22 -> CHAVAN HARIPRIYA SATISH | H23: =SUM(C23:G23) -> 0
A24: ='Summary Sheet'!A23 -> 412 | B24: ='Summary Sheet'!B23 -> CHAVAN NEHA BHIVSEN | H24: =SUM(C24:G24) -> 0
... A81: ='Summary Sheet'!A80 -> 469 | B81: ='Summary Sheet'!B80 -> GENDEWAD VEDIKA SHIVAJI | H81: =SUM(C81:G81) -> 0

Sheet Basic Electrical
A1: BHARATI VIDYAPEETH’S
A2: COLLEGE OF ENGINEERING FOR WOMEN, PUNE
A3: DEPARTMENT OF ENGINEERING SCIENCES AND ALLIED ENGINEERING
A4: Academic Year | B4: 2024-25
A5: Subject
A6: Semester
A7: Class | B7: F.E. | C7: Division
C8: Comprehensive Continuous Evaluation | H8: Total Marks | I8: Overall Attendance
A9: Roll No | B9: Name of Student | C9: Unit 1 | D9: Unit 2 | E9: Unit 3 | F9: Unit 4 | G9: Unit 5
C10: Unit Test | E10: Assignment /Case Study | G10: Seminar Presentation/Open book Test/Quiz
B11: Marks | C11: 6 | D11: 6 | E11: 6 | F11: 6 | G11: 6 | H11: =SUM(C11:G11) -> 30
B12: Date of Conduction | H12: =SUM(C12:G12) -> 0
A13: ='Summary Sheet'!A12 -> 401 | B13: ='Summary Sheet'!B12 -> TIWARY ADITA AJIT | H13: =SUM(C13:G13) -> 0
A14: ='Summary Sheet'!A13 -> 402 | B14: ='Summary Sheet'!B13 -> FULZELE AMRUTA HIRALAL | H14: =SUM(C14:G14) -> 0
A15: ='Summary Sheet'!A14 -> 403 | B15: ='Summary Sheet'!B14 -> ANBHULE ADITI NAMDEO | H15: =SUM(C15:G15) -> 0
A16: ='Summary Sheet'!A15 -> 404 | B16: ='Summary Sheet'!B15 -> ANBHULE SHIVANI SANDIP | H16: =SUM(C16:G16) -> 0
A17: ='Summary Sheet'!A16 -> 405 | B17: ='Summary Sheet'!B16 -> SAI PRAJNA B | H17: =SUM(C17:G17) -> 0
A18: ='Summary Sheet'!A17 -> 406 | B18: ='Summary Sheet'!B17 -> BADAGU GRISHMA GANESH | H18: =SUM(C18:G18) -> 0
A19: ='Summary Sheet'!A18 -> 407 | B19: ='Summary Sheet'!B18 -> BANDAL KAVERI MOHAN | H19: =SUM(C19:G19) -> 0
A20: ='Summary Sheet'!A19 -> 408 | B20: ='Summary Sheet'!B19 -> BARVE ASMITA ABHISHEK | H20: =SUM(C20:G20) -> 0
A21: ='Summary Sheet'!A20 -> 409 | B21: ='Summary Sheet'!B20 -> BHOSALE MIHIKA MANSING | H21: =SUM(C21:G21) -> 0
A22: ='Summary Sheet'!A21 -> 410 | B22: ='Summary Sheet'!B21 -> BONDRE ASMITA KAILAS | H22: =SUM(C22:G22) -> 0
A23: ='Summary Sheet'!A22 -> 411 | B23: ='Summary Sheet'!B22 -> CHAVAN HARIPRIYA SATISH | H23: =SUM(C23:G23) -> 0
A24: ='Summary Sheet'!A23 -> 412 | B24: ='Summary Sheet'!B23 -> CHAVAN NEHA BHIVSEN | H24: =SUM(C24:G24) -> 0
... A81: ='Summary Sheet'!A80 -> 469 | B81: ='Summary Sheet'!B80 -> GENDEWAD VEDIKA SHIVAJI | H81: =SUM(C81:G81) -> 0

Sheet Engg. Mechanics
A1: BHARATI VIDYAPEETH’S
A2: COLLEGE OF ENGINEERING FOR WOMEN, PUNE
A3: DEPARTMENT OF ENGINEERING SCIENCES AND ALLIED ENGINEERING
A4: Academic Year | B4: 2024-25
A5: Subject
A6: Semester
A7: Class | B7: F.E. | C7: Division
C8: Comprehensive Continuous Evaluation | H8: Total Marks | I8: Overall Attendance
A9: Roll No | B9: Name of Student | C9: Unit 1 | D9: Unit 2 | E9: Unit 3 | F9: Unit 4 | G9: Unit 5
C10: Unit Test | E10: Assignment /Case Study | G10: Seminar Presentation/Open book Test/Quiz
B11: Marks | C11: 6 | D11: 6 | E11: 6 | F11: 6 | G11: 6 | H11: =SUM(C11:G11) -> 30
B12: Date of Conduction | H12: =SUM(C12:G12) -> 0
A13: ='Summary Sheet'!A12 -> 401 | B13: ='Summary Sheet'!B12 -> TIWARY ADITA AJIT | H13: =SUM(C13:G13) -> 0
A14: ='Summary Sheet'!A13 -> 402 | B14: ='Summary Sheet'!B13 -> FULZELE AMRUTA HIRALAL | H14: =SUM(C14:G14) -> 0
A15: ='Summary Sheet'!A14 -> 403 | B15: ='Summary Sheet'!B14 -> ANBHULE ADITI NAMDEO | H15: =SUM(C15:G15) -> 0
A16: ='Summary Sheet'!A15 -> 404 | B16: ='Summary Sheet'!B15 -> ANBHULE SHIVANI SANDIP | H16: =SUM(C16:G16) -> 0
A17: ='Summary Sheet'!A16 -> 405 | B17: ='Summary Sheet'!B16 -> SAI PRAJNA B | H17: =SUM(C17:G17) -> 0
A18: ='Summary Sheet'!A17 -> 406 | B18: ='Summary Sheet'!B17 -> BADAGU GRISHMA GANESH | H18: =SUM(C18:G18) -> 0
A19: ='Summary Sheet'!A18 -> 407 | B19: ='Summary Sheet'!B18 -> BANDAL KAVERI MOHAN | H19: =SUM(C19:G19) -> 0
A20: ='Summary Sheet'!A19 -> 408 | B20: ='Summary Sheet'!B19 -> BARVE ASMITA ABHISHEK | H20: =SUM(C20:G20) -> 0
A21: ='Summary Sheet'!A20 -> 409 | B21: ='Summary Sheet'!B20 -> BHOSALE MIHIKA MANSING | H21: =SUM(C21:G21) -> 0
A22: ='Summary Sheet'!A21 -> 410 | B22: ='Summary Sheet'!B21 -> BONDRE ASMITA KAILAS | H22: =SUM(C22:G22) -> 0
A23: ='Summary Sheet'!A22 -> 411 | B23: ='Summary Sheet'!B22 -> CHAVAN HARIPRIYA SATISH | H23: =SUM(C23:G23) -> 0
A24: ='Summary Sheet'!A23 -> 412 | B24: ='Summary Sheet'!B23 -> CHAVAN NEHA BHIVSEN | H24: =SUM(C24:G24) -> 0
... A81: ='Summary Sheet'!A80 -> 469 | B81: ='Summary Sheet'!B80 -> GENDEWAD VEDIKA SHIVAJI | H81: =SUM(C81:G81) -> 0

Sheet FPL
A1: BHARATI VIDYAPEETH’S
A2: COLLEGE OF ENGINEERING FOR WOMEN, PUNE
A3: DEPARTMENT OF ENGINEERING SCIENCES AND ALLIED ENGINEERING
A4: Academic Year | B4: 2024-25
A5: Subject
A6: Semester
A7: Class | B7: F.E. | C7: Division
C8: Comprehensive Continuous Evaluation | H8: Total Marks | I8: Overall Attendance
A9: Roll No | B9: Name of Student | C9: Unit 1 | D9: Unit 2 | E9: Unit 3 | F9: Unit 4 | G9: Unit 5
C10: Unit Test | E10: Assignment /Case Study | G10: Seminar Presentation/Open book Test/Quiz
B11: Marks | C11: 6 | D11: 6 | E11: 6 | F11: 6 | G11: 6 | H11: =SUM(C11:G11) -> 30
B12: Date of Conduction | H12: =SUM(C12:G12) -> 0
A13: ='Summary Sheet'!A12 -> 401 | B13: ='Summary Sheet'!B12 -> TIWARY ADITA AJIT | H13: =SUM(C13:G13) -> 0
A14: ='Summary Sheet'!A13 -> 402 | B14: ='Summary Sheet'!B13 -> FULZELE AMRUTA HIRALAL | H14: =SUM(C14:G14) -> 0
A15: ='Summary Sheet'!A14 -> 403 | B15: ='Summary Sheet'!B14 -> ANBHULE ADITI NAMDEO | H15: =SUM(C15:G15) -> 0
A16: ='Summary Sheet'!A15 -> 404 | B16: ='Summary Sheet'!B15 -> ANBHULE SHIVANI SANDIP | H16: =SUM(C16:G16) -> 0
A17: ='Summary Sheet'!A16 -> 405 | B17: ='Summary Sheet'!B16 -> SAI PRAJNA B | H17: =SUM(C17:G17) -> 0
A18: ='Summary Sheet'!A17 -> 406 | B18: ='Summary Sheet'!B17 -> BADAGU GRISHMA GANESH | H18: =SUM(C18:G18) -> 0
A19: ='Summary Sheet'!A18 -> 407 | B19: ='Summary Sheet'!B18 -> BANDAL KAVERI MOHAN | H19: =SUM(C19:G19) -> 0
A20: ='Summary Sheet'!A19 -> 408 | B20: ='Summary Sheet'!B19 -> BARVE ASMITA ABHISHEK | H20: =SUM(C20:G20) -> 0
A21: ='Summary Sheet'!A20 -> 409 | B21: ='Summary Sheet'!B20 -> BHOSALE MIHIKA MANSING | H21: =SUM(C21:G21) -> 0
A22: ='Summary Sheet'!A21 -> 410 | B22: ='Summary Sheet'!B21 -> BONDRE ASMITA KAILAS | H22: =SUM(C22:G22) -> 0
A23: ='Summary Sheet'!A22 -> 411 | B23: ='Summary Sheet'!B22 -> CHAVAN HARIPRIYA SATISH | H23: =SUM(C23:G23) -> 0
A24: ='Summary Sheet'!A23 -> 412 | B24: ='Summary Sheet'!B23 -> CHAVAN NEHA BHIVSEN | H24: =SUM(C24:G24) -> 0
... A81: ='Summary Sheet'!A80 -> 469 | B81: ='Summary Sheet'!B80 -> GENDEWAD VEDIKA SHIVAJI | H81: =SUM(C81:G81) -> 0
